[2023-11-23T01:05:47.045+0000] {taskinstance.py:1159} INFO - Dependencies all met for dep_context=non-requeueable deps ti=<TaskInstance: our_dag_with_python_operator_v01.greet manual__2023-11-23T01:05:45.198923+00:00 [queued]>
[2023-11-23T01:05:47.052+0000] {taskinstance.py:1159} INFO - Dependencies all met for dep_context=requeueable deps ti=<TaskInstance: our_dag_with_python_operator_v01.greet manual__2023-11-23T01:05:45.198923+00:00 [queued]>
[2023-11-23T01:05:47.052+0000] {taskinstance.py:1361} INFO - Starting attempt 1 of 6
[2023-11-23T01:05:47.062+0000] {taskinstance.py:1382} INFO - Executing <Task(PythonOperator): greet> on 2023-11-23 01:05:45.198923+00:00
[2023-11-23T01:05:47.065+0000] {standard_task_runner.py:57} INFO - Started process 3354 to run task
[2023-11-23T01:05:47.069+0000] {standard_task_runner.py:84} INFO - Running: ['***', 'tasks', 'run', 'our_dag_with_python_operator_v01', 'greet', 'manual__2023-11-23T01:05:45.198923+00:00', '--job-id', '14', '--raw', '--subdir', 'DAGS_FOLDER/dag_with_python_operator.py', '--cfg-path', '/tmp/tmpuuuds7m4']
[2023-11-23T01:05:47.072+0000] {standard_task_runner.py:85} INFO - Job 14: Subtask greet
[2023-11-23T01:05:47.116+0000] {task_command.py:416} INFO - Running <TaskInstance: our_dag_with_python_operator_v01.greet manual__2023-11-23T01:05:45.198923+00:00 [running]> on host e2b63e65e4c5
[2023-11-23T01:05:47.186+0000] {taskinstance.py:1662} INFO - Exporting env vars: AIRFLOW_CTX_DAG_OWNER='harsha' AIRFLOW_CTX_DAG_ID='our_dag_with_python_operator_v01' AIRFLOW_CTX_TASK_ID='greet' AIRFLOW_CTX_EXECUTION_DATE='2023-11-23T01:05:45.198923+00:00' AIRFLOW_CTX_TRY_NUMBER='1' AIRFLOW_CTX_DAG_RUN_ID='manual__2023-11-23T01:05:45.198923+00:00'
[2023-11-23T01:05:47.187+0000] {taskinstance.py:1937} ERROR - Task failed with exception
Traceback (most recent call last):
  File "/home/airflow/.local/lib/python3.8/site-packages/airflow/operators/python.py", line 192, in execute
    return_value = self.execute_callable()
  File "/home/airflow/.local/lib/python3.8/site-packages/airflow/operators/python.py", line 209, in execute_callable
    return self.python_callable(*self.op_args, **self.op_kwargs)
  File "/opt/airflow/dags/dag_with_python_operator.py", line 12, in greet
    name = ti.xcom_pull(task_id='get_name')
  File "/home/airflow/.local/lib/python3.8/site-packages/airflow/utils/session.py", line 79, in wrapper
    return func(*args, session=session, **kwargs)
TypeError: xcom_pull() got an unexpected keyword argument 'task_id'
[2023-11-23T01:05:47.197+0000] {taskinstance.py:1400} INFO - Marking task as UP_FOR_RETRY. dag_id=our_dag_with_python_operator_v01, task_id=greet, execution_date=20231123T010545, start_date=20231123T010547, end_date=20231123T010547
[2023-11-23T01:05:47.205+0000] {standard_task_runner.py:104} ERROR - Failed to execute job 14 for task greet (xcom_pull() got an unexpected keyword argument 'task_id'; 3354)
[2023-11-23T01:05:47.243+0000] {local_task_job_runner.py:228} INFO - Task exited with return code 1
[2023-11-23T01:05:47.259+0000] {taskinstance.py:2778} INFO - 0 downstream tasks scheduled from follow-on schedule check
