[2023-11-23T23:30:39.301+0000] {taskinstance.py:1159} INFO - Dependencies all met for dep_context=non-requeueable deps ti=<TaskInstance: dag_with_postgres_operator.loading_data_from_csv_to_postgrestable manual__2023-11-23T20:02:45.255920+00:00 [queued]>
[2023-11-23T23:30:39.308+0000] {taskinstance.py:1159} INFO - Dependencies all met for dep_context=requeueable deps ti=<TaskInstance: dag_with_postgres_operator.loading_data_from_csv_to_postgrestable manual__2023-11-23T20:02:45.255920+00:00 [queued]>
[2023-11-23T23:30:39.308+0000] {taskinstance.py:1361} INFO - Starting attempt 4 of 6
[2023-11-23T23:30:39.319+0000] {taskinstance.py:1382} INFO - Executing <Task(PythonOperator): loading_data_from_csv_to_postgrestable> on 2023-11-23 20:02:45.255920+00:00
[2023-11-23T23:30:39.322+0000] {standard_task_runner.py:57} INFO - Started process 450 to run task
[2023-11-23T23:30:39.327+0000] {standard_task_runner.py:84} INFO - Running: ['***', 'tasks', 'run', 'dag_with_postgres_operator', 'loading_data_from_csv_to_postgrestable', 'manual__2023-11-23T20:02:45.255920+00:00', '--job-id', '52', '--raw', '--subdir', 'DAGS_FOLDER/dag_with_postgres_operator.py', '--cfg-path', '/tmp/tmplykr9b_v']
[2023-11-23T23:30:39.331+0000] {standard_task_runner.py:85} INFO - Job 52: Subtask loading_data_from_csv_to_postgrestable
[2023-11-23T23:30:39.391+0000] {task_command.py:416} INFO - Running <TaskInstance: dag_with_postgres_operator.loading_data_from_csv_to_postgrestable manual__2023-11-23T20:02:45.255920+00:00 [running]> on host 1f846b33469f
[2023-11-23T23:30:39.493+0000] {taskinstance.py:1662} INFO - Exporting env vars: AIRFLOW_CTX_DAG_OWNER='harsha' AIRFLOW_CTX_DAG_ID='dag_with_postgres_operator' AIRFLOW_CTX_TASK_ID='loading_data_from_csv_to_postgrestable' AIRFLOW_CTX_EXECUTION_DATE='2023-11-23T20:02:45.255920+00:00' AIRFLOW_CTX_TRY_NUMBER='4' AIRFLOW_CTX_DAG_RUN_ID='manual__2023-11-23T20:02:45.255920+00:00'
[2023-11-23T23:30:39.494+0000] {taskinstance.py:1937} ERROR - Task failed with exception
Traceback (most recent call last):
  File "/home/airflow/.local/lib/python3.8/site-packages/airflow/operators/python.py", line 192, in execute
    return_value = self.execute_callable()
  File "/home/airflow/.local/lib/python3.8/site-packages/airflow/operators/python.py", line 209, in execute_callable
    return self.python_callable(*self.op_args, **self.op_kwargs)
  File "/opt/airflow/dags/dag_with_postgres_operator.py", line 11, in load_csv_to_postgres
    with open('/opt/airflow/Airflow_Docker/sample_data.csv', mode='r') as file:
FileNotFoundError: [Errno 2] No such file or directory: '/opt/airflow/Airflow_Docker/sample_data.csv'
[2023-11-23T23:30:39.504+0000] {taskinstance.py:1400} INFO - Marking task as UP_FOR_RETRY. dag_id=dag_with_postgres_operator, task_id=loading_data_from_csv_to_postgrestable, execution_date=20231123T200245, start_date=20231123T233039, end_date=20231123T233039
[2023-11-23T23:30:39.513+0000] {standard_task_runner.py:104} ERROR - Failed to execute job 52 for task loading_data_from_csv_to_postgrestable ([Errno 2] No such file or directory: '/opt/airflow/Airflow_Docker/sample_data.csv'; 450)
[2023-11-23T23:30:39.543+0000] {local_task_job_runner.py:228} INFO - Task exited with return code 1
[2023-11-23T23:30:39.560+0000] {taskinstance.py:2778} INFO - 0 downstream tasks scheduled from follow-on schedule check
